<mujoco model="tatami">
  <compiler angle="degree" coordinate="local" inertiafromgeom="true" />
  <option integrator="RK4" timestep="0.01" />
  <size nconmax="1000" njmax="1000" />
  <default>
    <joint armature="1" damping="1" limited="true" />
  <default class="ant0"><geom conaffinity="1" condim="3" density="13.0" friction="1 0.5 0.5" margin="0.01" material="geom" rgba="0.5 0.25 0.25 1" />
    <motor ctrllimited="true" ctrlrange="-1. 1." />
  </default><default class="bug1"><geom conaffinity="1" condim="3" density="10.0" friction="1 0.5 0.5" margin="0.01" material="geom" rgba="0.25 0.5 0.5 1" />
    <motor ctrllimited="true" ctrlrange="-1. 1." />
  </default></default>
  <asset>
    <texture builtin="gradient" height="100" rgb1=".8 .8 1" rgb2="0 0 0" type="skybox" width="100" />
    <texture builtin="flat" height="1278" mark="cross" markrgb="1 1 1" name="texgeom" random="0.01" rgb1="0.8 0.6 0.4" rgb2="0.8 0.6 0.4" type="cube" width="127" />
    <texture builtin="flat" height="100" name="floorplane" rgb1=".2 0.2 0.2" rgb2="0 0 0" type="2d" width="100" />
    <texture builtin="flat" height="100" name="tatamiplane" rgb1=".65 0.57 0.31" rgb2="0 0 0" type="2d" width="100" />
    <material name="MatPlane" reflectance="0.1" shininess="1" specular="1" texrepeat="1 1" texture="floorplane" />
    <material name="TatamiPlane" reflectance="0.25" shininess="1" specular="1" texrepeat="1 1" texture="tatamiplane" />
    <material name="geom" texture="texgeom" texuniform="true" />
  </asset>
  <worldbody>
    <light cutoff="100" diffuse="1 1 1" dir="0 0 -1.3" directional="true" exponent="2" pos="0 0 1.3" specular=".5 .5 .5" />
    <geom conaffinity="1" condim="3" contype="1" friction="1 .7 .7" material="MatPlane" name="floor" pos="0 0 -.025" rgba="1 1 1 1" size="20 20 0.125" type="plane" />
    
    <geom conaffinity="1" condim="3" contype="1" friction="1 .7 .7" material="TatamiPlane" name="tatami" pos="0 0 0.25" size="8.30 8.30 0.25" type="box" />
    <geom fromto="-8.00 8.00 0.5  8.00 8.00 0.5" name="topborder" rgba=".18 .23 .38 1" size=".03" type="cylinder" />
    <geom fromto="8.00 -8.00 0.5  8.00 8.00 0.5" name="rightborder" rgba=".18 .23 .38 1" size=".03" type="cylinder" />
    <geom fromto="-8.00 -8.00 0.5  8.00 -8.00 0.5" name="bottomborder" rgba=".18 .23 .38 1" size=".03" type="cylinder" />
    <geom fromto="-8.00 -8.00 0.5  -8.00 8.00 0.5" name="leftborder" rgba=".18 .23 .38 1" size=".03" type="cylinder" />
    
    <body name="south_wall" pos="0 -8.15 1.5">
      <geom name="s_wall" rgba="0.3 0.3 0.3 1" size="8.35 0.20 1.5" type="box" />
    </body>
    <body name="north_wall" pos="0 8.15 1.5">
      <geom name="n_wall" rgba="0.3 0.3 0.3 1" size="2 0.20 1.5" type="box" />
    </body>

    <body name="west_wall" pos="-8.15 -2 1.5">
      <geom name="w_wall" rgba="0.3 0.3 0.3 1" size="0.2 5.95 1.5" type="box" />
    </body>
    <body name="east_wall" pos="8.15 -2 1.5">
      <geom name="e_wall" rgba="0.3 0.3 0.3 1" size="0.2 5.95 1.5" type="box" />
    </body>

    <body name="northwest" pos="-5.175 6.15 1.5">
      <geom name="nw_wall" rgba="0.3 0.3 0.3 1" size="3.175 2.2 1.5" type="box" />
    </body>
    <body name="northeast" pos="5.175 6.15 1.5">
      <geom name="ne_wall" rgba="0.3 0.3 0.3 1" size="3.175 2.2 1.5" type="box" />
    </body>
    
    <body name="pushable_obj" pos="0 0 1.5">
      <geom contype="1" mass="1" material="" rgba="1 1 1 1" size="1 1 1" type="box" />
      <joint armature="0" axis="1 0 0" damping="0.0" limited="true" margin="0.01" pos="0 0 0" range="-10 10" type="slide" />
      <joint armature="0" axis="0 1 0" damping="0.0" limited="true" margin="0.01" pos="0 0 0" range="-10 10" type="slide" />
    </body>

  <body name="ant0/torso" pos="1.5 0.0 0.75">
    <geom class="ant0" name="ant0/torso_geom" pos="0 0 0" size="0.25" type="sphere" />
    <joint armature="0" damping="0" limited="false" margin="0.01" name="ant0/root" pos="0 0 0" type="free" />
    
    <body name="ant0/front_left_leg" pos="0 0 0">
      <geom class="ant0" fromto="0.0 0.0 0.0 -0.2 0.2 0.0" name="ant0/aux_1_geom" size="0.08" type="capsule" />
      <body name="ant0/aux_11" pos="-0.2 0.2 0">
        <joint axis="0 0 1" name="ant0/hip_1" pos="0.0 0.0 0.0" range="-30 30" type="hinge" />
        <geom class="ant0" fromto="0.0 0.0 0.0 -0.2 0.2 0.0" name="ant0/front_left_leg_geom" size="0.08" type="capsule" />
        <body name="ant0/aux_12" pos="-0.2 0.2 0">
          <joint axis="1 1 0" name="ant0/ankle_1" pos="0.0 0.0 0.0" range="-70 -30" type="hinge" />
          <geom class="ant0" fromto="0.0 0.0 0.0 -0.4 0.4 0.0" name="ant0/front_left_ankle_geom" size="0.08" type="capsule" />
        </body>
      </body>
    </body>
    
    <body name="ant0/front_right_leg" pos="0 0 0">
      <geom class="ant0" fromto="0.0 0.0 0.0 0.2 0.2 0.0" name="ant0/aux_2_geom" size="0.08" type="capsule" />
      <body name="ant0/aux_21" pos="0.2 0.2 0">
        <joint axis="0 0 1" name="ant0/hip_2" pos="0.0 0.0 0.0" range="-30 30" type="hinge" />
        <geom class="ant0" fromto="0.0 0.0 0.0 0.2 0.2 0.0" name="ant0/front_right_leg_geom" size="0.08" type="capsule" />
        <body name="ant0/aux_22" pos="0.2 0.2 0">
          <joint axis="-1 1 0" name="ant0/ankle_2" pos="0.0 0.0 0.0" range="30 70" type="hinge" />
          <geom class="ant0" fromto="0.0 0.0 0.0 0.4 0.4 0.0" name="ant0/front_right_ankle_geom" size="0.08" type="capsule" />
        </body>
      </body>
    </body>
    
    <body name="ant0/back_left_leg" pos="0 0 0">
      <geom class="ant0" fromto="0.0 0.0 0.0 -0.2 -0.2 0.0" name="ant0/aux_3_geom" size="0.08" type="capsule" />
      <body name="ant0/aux_31" pos="-0.2 -0.2 0">
        <joint axis="0 0 1" name="ant0/hip_3" pos="0.0 0.0 0.0" range="-30 30" type="hinge" />
        <geom class="ant0" fromto="0.0 0.0 0.0 -0.2 -0.2 0.0" name="ant0/back_left_leg_geom" size="0.08" type="capsule" />
        <body name="ant0/aux_32" pos="-0.2 -0.2 0">
          <joint axis="-1 1 0" name="ant0/ankle_3" pos="0.0 0.0 0.0" range="-70 -30" type="hinge" />
          <geom class="ant0" fromto="0.0 0.0 0.0 -0.4 -0.4 0.0" name="ant0/back_left_ankle_geom" size="0.08" type="capsule" />
        </body>
      </body>
    </body>
    <body name="ant0/back_right_leg" pos="0 0 0">
      <geom class="ant0" fromto="0.0 0.0 0.0 0.2 -0.2 0.0" name="ant0/aux_4_geom" size="0.08" type="capsule" />
      <body name="ant0/aux_41" pos="0.2 -0.2 0">
        <joint axis="0 0 1" name="ant0/hip_4" pos="0.0 0.0 0.0" range="-30 30" type="hinge" />
        <geom class="ant0" fromto="0.0 0.0 0.0 0.2 -0.2 0.0" name="ant0/back_right_leg_geom" size="0.08" type="capsule" />
        <body name="ant0/aux_42" pos="0.2 -0.2 0">
          <joint axis="1 1 0" name="ant0/ankle_4" pos="0.0 0.0 0.0" range="30 70" type="hinge" />
          <geom class="ant0" fromto="0.0 0.0 0.0 0.4 -0.4 0.0" name="ant0/back_right_ankle_geom" size="0.08" type="capsule" />
        </body>
      </body>
    </body>
  </body>
  <body name="bug1/torso" pos="-1.5 1.8369701987210297e-16 0.75">
    <geom class="bug1" name="bug1/torso_geom" pos="0 0 0" size="0.25" type="sphere" />
    <joint armature="0" damping="0" limited="false" margin="0.01" name="bug1/root" pos="0 0 0" type="free" />
    
    <body name="bug1/back_left_leg" pos="0 0 0">
      <geom class="bug1" fromto="0 0 0 0.18 0.215 0" name="bug1/aux_1_geom" size="0.08" type="capsule" />
      <body name="bug1/aux_11" pos="0.18 0.215 0">
        <joint axis="0 0 1" name="bug1/hip_1" pos="0 0 0" range="-30 30" type="hinge" />
        <geom class="bug1" fromto="0 0 0 0.18 0.215 0" name="bug1/back_left_leg_geom" size="0.08" type="capsule" />
        <body name="bug1/aux_12" pos="0.18 0.215 0">
          <joint axis="-1 1 0" name="bug1/ankle_1" pos="0 0 0" range="30 70" type="hinge" />
          <geom class="bug1" fromto="0 0 0 0.324 0.387 0" name="bug1/back_left_ankle_geom" size="0.08" type="capsule" />
        </body>
      </body>
    </body>
    
    <body name="bug1/back_right_leg" pos="0 0 0">
      <geom class="bug1" fromto="0 0 0 -0.18 0.215 0" name="bug1/aux_2_geom" size="0.08" type="capsule" />
      <body name="bug1/aux_21" pos="-0.18 0.215 0">
        <joint axis="0 0 1" name="bug1/hip_2" pos="0 0 0" range="-30 30" type="hinge" />
        <geom class="bug1" fromto="0 0 0 -0.18 0.215 0" name="bug1/back_right_leg_geom" size="0.08" type="capsule" />
        <body name="bug1/aux_22" pos="-0.18 0.215 0">
          <joint axis="1 1 0" name="bug1/ankle_2" pos="0 0 0" range="-70 -30" type="hinge" />
          <geom class="bug1" fromto="0 0 0 -0.324 0.387 0" name="bug1/back_right_ankle_geom" size="0.08" type="capsule" />
        </body>
      </body>
    </body>
    
    <body name="bug1/middle_right_leg" pos="0 0 0">
      <geom class="bug1" fromto="0 0 0 -0.2 0 0" name="bug1/aux_3_geom" size="0.08" type="capsule" />
      <body name="bug1/aux_31" pos="-0.2 0 0">
        <joint axis="0 0 1" name="bug1/hip_3" pos="0 0 0" range="-30 30" type="hinge" />
        <geom class="bug1" fromto="0 0 0 -0.275 0 0" name="bug1/middle_right_leg_geom" size="0.08" type="capsule" />
        <body name="bug1/aux_32" pos="-0.275 0 0">
          <joint axis="0 1 0" name="bug1/ankle_3" pos="0 0 0" range="-70 -30" type="hinge" />
          <geom class="bug1" fromto="0 0 0 -0.55 0 0" name="bug1/middle_right_ankle_geom" size="0.08" type="capsule" />
        </body>
      </body>
    </body>
    
    <body name="bug1/middle_left_leg" pos="0 0 0">
      <geom class="bug1" fromto="0 0 0 0.2 0 0" name="bug1/aux_4_geom" size="0.08" type="capsule" />
      <body name="bug1/aux_41" pos="0.2 0 0">
        <joint axis="0 0 1" name="bug1/hip_4" pos="0 0 0" range="-30 30" type="hinge" />
        <geom class="bug1" fromto="0 0 0 0.275 0 0" name="bug1/middle_left_leg_geom" size="0.08" type="capsule" />
        <body name="bug1/aux_42" pos="0.275 0 0">
          <joint axis="0 1 0" name="bug1/ankle_4" pos="0 0 0" range="30 70" type="hinge" />
          <geom class="bug1" fromto="0 0 0 0.55 0 0" name="bug1/middle_left_ankle_geom" size="0.08" type="capsule" />
        </body>
      </body>
    </body>
    
    <body name="bug1/front_right_leg" pos="0 0 0">
      <geom class="bug1" fromto="0 0 0 -0.18 -0.215 0" name="bug1/aux_5_geom" size="0.08" type="capsule" />
      <body name="bug1/aux_51" pos="-0.18 -0.215 0">
        <joint axis="0 0 1" name="bug1/hip_5" pos="0 0 0" range="-30 30" type="hinge" />
        <geom class="bug1" fromto="0 0 0 -0.18 -0.215 0" name="bug1/front_right_leg_geom" size="0.08" type="capsule" />
        <body name="bug1/aux_52" pos="-0.18 -0.215 0">
          <joint axis="-1 1 0" name="bug1/ankle_5" pos="0 0 0" range="-70 -30" type="hinge" />
          <geom class="bug1" fromto="0 0 0 -0.324 -0.387 0" name="bug1/front_right_ankle_geom" size="0.08" type="capsule" />
        </body>
      </body>
    </body>
    
    <body name="bug1/front_left_leg" pos="0 0 0">
      <geom class="bug1" fromto="0 0 0 0.18 -0.215 0" name="bug1/aux_6_geom" size="0.08" type="capsule" />
      <body name="bug1/aux_61" pos="0.18 -0.215 0">
        <joint axis="0 0 1" name="bug1/hip_6" pos="0 0 0" range="-30 30" type="hinge" />
        <geom class="bug1" fromto="0 0 0 0.18 -0.215 0" name="bug1/front_left_leg_geom" size="0.08" type="capsule" />
        <body name="bug1/aux_62" pos="0.18 -0.215 0">
          <joint axis="1 1 0" name="bug1/ankle_6" pos="0 0 0" range="30 70" type="hinge" />
          <geom class="bug1" fromto="0 0 0 0.324 -0.387 0" name="bug1/front_left_ankle_geom" size="0.08" type="capsule" />
        </body>
      </body>
    </body>
  </body>
  </worldbody>
<actuator>
    <motor class="ant0" ctrllimited="true" ctrlrange="-1.0 1.0" gear="150" joint="ant0/hip_1" />
    <motor class="ant0" ctrllimited="true" ctrlrange="-1.0 1.0" gear="150" joint="ant0/ankle_1" />
    <motor class="ant0" ctrllimited="true" ctrlrange="-1.0 1.0" gear="150" joint="ant0/hip_2" />
    <motor class="ant0" ctrllimited="true" ctrlrange="-1.0 1.0" gear="150" joint="ant0/ankle_2" />
    <motor class="ant0" ctrllimited="true" ctrlrange="-1.0 1.0" gear="150" joint="ant0/hip_3" />
    <motor class="ant0" ctrllimited="true" ctrlrange="-1.0 1.0" gear="150" joint="ant0/ankle_3" />
    <motor class="ant0" ctrllimited="true" ctrlrange="-1.0 1.0" gear="150" joint="ant0/hip_4" />
    <motor class="ant0" ctrllimited="true" ctrlrange="-1.0 1.0" gear="150" joint="ant0/ankle_4" />
  <motor class="bug1" ctrllimited="true" ctrlrange="-1.0 1.0" gear="150" joint="bug1/hip_1" />
    <motor class="bug1" ctrllimited="true" ctrlrange="-1.0 1.0" gear="150" joint="bug1/ankle_1" />
    <motor class="bug1" ctrllimited="true" ctrlrange="-1.0 1.0" gear="150" joint="bug1/hip_2" />
    <motor class="bug1" ctrllimited="true" ctrlrange="-1.0 1.0" gear="150" joint="bug1/ankle_2" />
    <motor class="bug1" ctrllimited="true" ctrlrange="-1.0 1.0" gear="150" joint="bug1/hip_3" />
    <motor class="bug1" ctrllimited="true" ctrlrange="-1.0 1.0" gear="150" joint="bug1/ankle_3" />
    <motor class="bug1" ctrllimited="true" ctrlrange="-1.0 1.0" gear="150" joint="bug1/hip_4" />
    <motor class="bug1" ctrllimited="true" ctrlrange="-1.0 1.0" gear="150" joint="bug1/ankle_4" />
    <motor class="bug1" ctrllimited="true" ctrlrange="-1.0 1.0" gear="150" joint="bug1/hip_5" />
    <motor class="bug1" ctrllimited="true" ctrlrange="-1.0 1.0" gear="150" joint="bug1/ankle_5" />
    <motor class="bug1" ctrllimited="true" ctrlrange="-1.0 1.0" gear="150" joint="bug1/hip_6" />
    <motor class="bug1" ctrllimited="true" ctrlrange="-1.0 1.0" gear="150" joint="bug1/ankle_6" />
  </actuator>
  <sensor>
    
    <jointpos joint="ant0/hip_1" name="ant0/pos_hip_1" />
    <jointpos joint="ant0/hip_2" name="ant0/pos_hip_2" />
    <jointpos joint="ant0/hip_3" name="ant0/pos_hip_3" />
    <jointpos joint="ant0/hip_4" name="ant0/pos_hip_4" />
    <jointpos joint="ant0/ankle_1" name="ant0/pos_ankle_1" />
    <jointpos joint="ant0/ankle_2" name="ant0/pos_ankle_2" />
    <jointpos joint="ant0/ankle_3" name="ant0/pos_ankle_3" />
    <jointpos joint="ant0/ankle_4" name="ant0/pos_ankle_4" />
    
    <jointvel joint="ant0/hip_1" name="ant0/vel_hip_1" />
    <jointvel joint="ant0/hip_2" name="ant0/vel_hip_2" />
    <jointvel joint="ant0/hip_3" name="ant0/vel_hip_3" />
    <jointvel joint="ant0/hip_4" name="ant0/vel_hip_4" />
    <jointvel joint="ant0/ankle_1" name="ant0/vel_ankle_1" />
    <jointvel joint="ant0/ankle_2" name="ant0/vel_ankle_2" />
    <jointvel joint="ant0/ankle_3" name="ant0/vel_ankle_3" />
    <jointvel joint="ant0/ankle_4" name="ant0/vel_ankle_4" />
  <jointpos joint="bug1/hip_1" name="bug1/pos_hip_1" />
    <jointpos joint="bug1/hip_2" name="bug1/pos_hip_2" />
    <jointpos joint="bug1/hip_3" name="bug1/pos_hip_3" />
    <jointpos joint="bug1/hip_4" name="bug1/pos_hip_4" />
    <jointpos joint="bug1/hip_5" name="bug1/pos_hip_5" />
    <jointpos joint="bug1/hip_6" name="bug1/pos_hip_6" />
    <jointpos joint="bug1/ankle_1" name="bug1/pos_ankle_1" />
    <jointpos joint="bug1/ankle_2" name="bug1/pos_ankle_2" />
    <jointpos joint="bug1/ankle_3" name="bug1/pos_ankle_3" />
    <jointpos joint="bug1/ankle_4" name="bug1/pos_ankle_4" />
    <jointpos joint="bug1/ankle_5" name="bug1/pos_ankle_5" />
    <jointpos joint="bug1/ankle_6" name="bug1/pos_ankle_6" />
    
    <jointvel joint="bug1/hip_1" name="bug1/vel_hip_1" />
    <jointvel joint="bug1/hip_2" name="bug1/vel_hip_2" />
    <jointvel joint="bug1/hip_3" name="bug1/vel_hip_3" />
    <jointvel joint="bug1/hip_4" name="bug1/vel_hip_4" />
    <jointvel joint="bug1/hip_5" name="bug1/vel_hip_5" />
    <jointvel joint="bug1/hip_6" name="bug1/vel_hip_6" />
    <jointvel joint="bug1/ankle_1" name="bug1/vel_ankle_1" />
    <jointvel joint="bug1/ankle_2" name="bug1/vel_ankle_2" />
    <jointvel joint="bug1/ankle_3" name="bug1/vel_ankle_3" />
    <jointvel joint="bug1/ankle_4" name="bug1/vel_ankle_4" />
    <jointvel joint="bug1/ankle_5" name="bug1/vel_ankle_5" />
    <jointvel joint="bug1/ankle_6" name="bug1/vel_ankle_6" />
  </sensor>
</mujoco>