<mujoco model="tatami">
  <compiler angle="degree" coordinate="local" inertiafromgeom="true"/>
  <option integrator="RK4" timestep="0.01"/>
  <size nconmax="1000" njmax="1000"/>
  <default>
    <joint armature="1" damping="1" limited="true"/>
  </default>
  <asset>
    <texture builtin="gradient" height="100" rgb1=".8 .8 1" rgb2="0 0 0" type="skybox" width="100"/>
    <texture builtin="flat" height="1278" mark="cross" markrgb="1 1 1" name="texgeom" random="0.01" rgb1="0.8 0.6 0.4" rgb2="0.8 0.6 0.4" type="cube" width="127"/>
    <texture builtin="flat" height="100" name="floorplane" rgb1=".2 0.2 0.2" rgb2="0 0 0" type="2d" width="100"/>
    <texture builtin="flat" height="100" name="tatamiplane" rgb1=".65 0.57 0.31" rgb2="0 0 0" type="2d" width="100"/>
    <material name="MatPlane" reflectance="0.1" shininess="1" specular="1" texrepeat="1 1" texture="floorplane"/>
    <material name="TatamiPlane" reflectance="0.25" shininess="1" specular="1" texrepeat="1 1" texture="tatamiplane"/>
    <material name="geom" texture="texgeom" texuniform="true"/>
  </asset>
  <worldbody>
    <light cutoff="100" diffuse="1 1 1" dir="0 0 -1.3" directional="true" exponent="2" pos="0 0 1.3" specular=".5 .5 .5"/>
    <geom contype="1" conaffinity="1" friction="1 .7 .7" condim="3" material="MatPlane" name="floor" pos="0 0 -.025" rgba="1 1 1 1" size="20 20 0.125" type="plane"/>
    <!-- <geom contype="1" conaffinity="1" friction="1 .1 .1" condim="3" material="TatamiPlane" name="tatami" pos="0 0 0" rgba=".9 .9 .9 1" size="2 2 0.125" type="plane"/> -->
    <geom conaffinity="1" condim="3" contype="1" friction="1 .7 .7" material="TatamiPlane" name="tatami" size="2.3 2.3 .25" pos="0 0 0.25" type="box" />
    <geom fromto="-2 2 .5  2 2 .5" name="topborder" rgba=".18 .23 .38 1" size=".03" type="cylinder"/>
    <geom fromto="2 -2 .5  2 2 .5" name="rightborder" rgba=".18 .23 .38 1" size=".03" type="cylinder"/>
    <geom fromto="-2 -2 .5  2 -2 .5" name="bottomborder" rgba=".18 .23 .38 1" size=".03" type="cylinder"/>
    <geom fromto="-2 -2 .5  -2 2 .5" name="leftborder" rgba=".18 .23 .38 1" size=".03" type="cylinder"/>
    <!-- Walls -->
    <body name="south_wall" pos="0 -8.15 1.5">
      <geom name="s_wall" type="box" size="8.35 0.20 1.5" rgba="0.3 0.3 0.3 1"/>
    </body>
    <body name="north_wall" pos="0 8.15 1.5">
      <geom name="n_wall" type="box" size="8.35 0.20 1.5" rgba="0.3 0.3 0.3 1"/>
    </body>

    <body name="west_wall" pos="-8.15 0 1.5">
      <geom name="w_wall" type="box" size="0.2 7.95 1.5" rgba="0.3 0.3 0.3 1"/>
    </body>
    <body name="east_wall" pos="8.15 0 1.5">
      <geom name="e_wall" type="box" size="0.2 7.95 1.5" rgba="0.3 0.3 0.3 1"/>
    </body>

    <body name="northwest" pos="8.15 0 1.5">
      <geom name="nw_wall" type="box" size="0.2 7.95 1.5" rgba="0.3 0.3 0.3 1"/>
    </body>
    <body name="northeast" pos="8.15 0 1.5">
      <geom name="ne_wall" type="box" size="0.2 7.95 1.5" rgba="0.3 0.3 0.3 1"/>
    </body>
    <!-- Add a pushable box -->
    <body name="pushable_obj" pos="0 0 1.5">
      <geom type="box" size="1 1 1" rgba="1 1 1 1" material="" mass="1" contype="1"/>
      <joint armature="0" axis="1 0 0" damping="0.0" limited="true" margin="0.01" range="-10 10" pos="0 0 0" type="slide"/>
      <joint armature="0" axis="0 1 0" damping="0.0" limited="true" margin="0.01" range="-10 10" pos="0 0 0" type="slide"/>
    </body>

  </worldbody>
</mujoco>
